<?xml version="1.0" encoding="UTF-8"?>
<testng-results ignored="0" total="3" passed="2" failed="1" skipped="0">
  <reporter-output>
  </reporter-output>
  <suite started-at="2024-11-16T14:46:11 EST" name="ExceptionSuite" finished-at="2024-11-16T14:46:12 EST" duration-ms="334">
    <groups>
    </groups>
    <test started-at="2024-11-16T14:46:11 EST" name="ExceptionTest" finished-at="2024-11-16T14:46:12 EST" duration-ms="334">
      <class name="testNGExceptionTest.TestException">
        <test-method signature="testAdd()[pri:0, instance:testNGExceptionTest.TestException@34bde49d]" started-at="2024-11-16T14:46:11 EST" name="testAdd" finished-at="2024-11-16T14:46:11 EST" duration-ms="119" status="PASS">
          <reporter-output>
          </reporter-output>
        </test-method> <!-- testAdd -->
        <test-method signature="testArthmenticException()[pri:0, instance:testNGExceptionTest.TestException@34bde49d]" started-at="2024-11-16T14:46:12 EST" name="testArthmenticException" finished-at="2024-11-16T14:46:12 EST" duration-ms="20" status="FAIL">
          <exception class="org.testng.TestException">
            <message>
              <![CDATA[
Method TestException.testArthmenticException()[pri:0, instance:testNGExceptionTest.TestException@34bde49d] should have thrown an exception of type class java.lang.ArithmeticException]]>
            </message>
            <full-stacktrace>
              <![CDATA[org.testng.TestException: 
Method TestException.testArthmenticException()[pri:0, instance:testNGExceptionTest.TestException@34bde49d] should have thrown an exception of type class java.lang.ArithmeticException
at org.testng.internal.invokers.ExpectedExceptionsHolder.noException(ExpectedExceptionsHolder.java:81)
at org.testng.internal.invokers.TestInvoker.considerExceptionsInternal(TestInvoker.java:895)
at org.testng.internal.invokers.TestInvoker.considerExceptions(TestInvoker.java:860)
at org.testng.internal.invokers.TestInvoker.invokeMethod(TestInvoker.java:741)
at org.testng.internal.invokers.TestInvoker.invokeTestMethod(TestInvoker.java:230)
at org.testng.internal.invokers.MethodRunner.runInSequence(MethodRunner.java:63)
at org.testng.internal.invokers.TestInvoker$MethodInvocationAgent.invoke(TestInvoker.java:992)
at org.testng.internal.invokers.TestInvoker.invokeTestMethods(TestInvoker.java:203)
at org.testng.internal.invokers.TestMethodWorker.invokeTestMethods(TestMethodWorker.java:154)
at org.testng.internal.invokers.TestMethodWorker.run(TestMethodWorker.java:134)
at java.base/java.util.ArrayList.forEach(ArrayList.java:1597)
at org.testng.TestRunner.privateRun(TestRunner.java:739)
at org.testng.TestRunner.run(TestRunner.java:614)
at org.testng.SuiteRunner.runTest(SuiteRunner.java:421)
at org.testng.SuiteRunner.runSequentially(SuiteRunner.java:413)
at org.testng.SuiteRunner.privateRun(SuiteRunner.java:373)
at org.testng.SuiteRunner.run(SuiteRunner.java:312)
at org.testng.SuiteRunnerWorker.runSuite(SuiteRunnerWorker.java:52)
at org.testng.SuiteRunnerWorker.run(SuiteRunnerWorker.java:95)
at org.testng.TestNG.runSuitesSequentially(TestNG.java:1274)
at org.testng.TestNG.runSuitesLocally(TestNG.java:1208)
at org.testng.TestNG.runSuites(TestNG.java:1112)
at org.testng.TestNG.run(TestNG.java:1079)
at org.testng.remote.AbstractRemoteTestNG.run(AbstractRemoteTestNG.java:115)
at org.testng.remote.RemoteTestNG.initAndRun(RemoteTestNG.java:293)
at org.testng.remote.RemoteTestNG.main(RemoteTestNG.java:91)
]]>
            </full-stacktrace>
          </exception> <!-- org.testng.TestException -->
          <reporter-output>
          </reporter-output>
        </test-method> <!-- testArthmenticException -->
        <test-method signature="testSubtract()[pri:0, instance:testNGExceptionTest.TestException@34bde49d]" started-at="2024-11-16T14:46:12 EST" name="testSubtract" finished-at="2024-11-16T14:46:12 EST" duration-ms="5" status="PASS">
          <reporter-output>
          </reporter-output>
        </test-method> <!-- testSubtract -->
      </class> <!-- testNGExceptionTest.TestException -->
    </test> <!-- ExceptionTest -->
  </suite> <!-- ExceptionSuite -->
</testng-results>
